Performing system checks...

System check identified no issues (0 silenced).
March 05, 2019 - 01:35:35
Django version 2.0.2, using settings 'mysite.settings'
Starting development server at http://127.0.0.1:8000/
Quit the server with CTRL-BREAK.
[05/Mar/2019 01:35:39] "GET / HTTP/1.1" 200 1910
[05/Mar/2019 01:35:42] "GET /n2t/new/ HTTP/1.1" 200 3222
Internal Server Error: /n2t/new/
Traceback (most recent call last):
  File "C:\Users\user\Anaconda3\lib\site-packages\django\core\handlers\exception
.py", line 35, in inner
    response = get_response(request)
  File "C:\Users\user\Anaconda3\lib\site-packages\django\core\handlers\base.py",
 line 128, in _get_response
    response = self.process_exception_by_middleware(e, request)
  File "C:\Users\user\Anaconda3\lib\site-packages\django\core\handlers\base.py",
 line 126, in _get_response
    response = wrapped_callback(request, *callback_args, **callback_kwargs)
  File "C:\Users\user\PycharmProjects\djangogirls\n2t\views.py", line 16, in not
e_new
    if form.is_valid():
UnboundLocalError: local variable 'form' referenced before assignment
[05/Mar/2019 01:35:48] "POST /n2t/new/ HTTP/1.1" 500 66066

(base) C:\Users\user\PycharmProjects\djangogirls>